Workbook

Sheet Module4_Transaction
B1: MODULE 4 · TRANSACTION ANALYTICS
B3: Banking & Financial Analytics Platform (Group 4) | Source: Transaction_Data (2,500 rows, Jan-2025 to Sep-2026) | Amounts in INR; volume shown in ₹ Lakh (1 Lakh = 100,000) | R3: Filter helper cells (auto)
B4: Filter: City | C4: All | E4: Filter: Year | F4: All | H4: ◄ pick from the dropdowns (yellow cells) | R4: City criterion | S4: =IF($C$4="All","*",$C$4) -> *
R5: From date | S5: =IF($F$4="All",DATE(2000,1,1),DATE($F$4,1,1)) -> 36526
B6: TOTAL TRANSACTIONS | D6: TOTAL VOLUME (₹ CRORE) | F6: AVG TICKET SIZE (₹) | H6: SUCCESS RATE | J6: FAILED RATE | L6: PENDING RATE | N6: INTERNATIONAL SHARE | R6: To date (excl.) | S6: =IF($F$4="All",DATE(2100,1,1),DATE($F$4+1,1,1)) -> 73051
B7: =COUNTIFS(Transaction_Data!$D$2:$D$5000,">="&$S$5,Transaction_Data!$D$2:$D$5000,"<"&$S$6,Transaction_Data!$H$2:$H$5000,$S$4) -> 2500 | D7: =SUMIFS(Transaction_Data!$F$2:$F$5000,Transaction_Data!$D$2:$D$5000,">="&$S$5,Transaction_Data!$D$2:$D$5000,"<"&$S$6,Transaction_Data!$H$2:$H$5000,$S$4)/10000000 -> 24.839974 | F7: =IFERROR(SUMIFS(Transaction_Data!$F$2:$F$5000,Transaction_Data!$D$2:$D$5000,">="&$S$5,Transaction_Data!$D$2:$D$5000,"<"&$S$6,Transaction_Data!$H$2:$H$5000,$S$4)/COUNTIFS(Transaction_Data!$D$2:$D$5000,">="&$S$5,Transaction_Data!$D$2:$D$5000,"<"&$S$6,Transaction_Data!$H$2:$H$5000,$S$4),0) -> 99359.897 | H7: =IFERROR(COUNTIFS(Transaction_Data!$D$2:$D$5000,">="&$S$5,Transaction_Data!$D$2:$D$5000,"<"&$S$6,Transaction_Data!$H$2:$H$5000,$S$4,Transaction_Data!$J$2:$J$5000,"Success")/COUNTIFS(Transaction_Data!$D$2:$D$5000,">="&$S$5,Transaction_Data!$D$2:$D$5000,"<"&$S$6,Transaction_Data!$H$2:$H$5000,$S$4),0) -> 0.8844 | J7: =IFERROR(COUNTIFS(Transaction_Data!$D$2:$D$5000,">="&$S$5,Transaction_Data!$D$2:$D$5000,"<"&$S$6,Transaction_Data!$H$2:$H$5000,$S$4,Transaction_Data!$J$2:$J$5000,"Failed")/COUNTIFS(Transaction_Data!$D$2:$D$5000,">="&$S$5,Transaction_Data!$D$2:$D$5000,"<"&$S$6,Transaction_Data!$H$2:$H$5000,$S$4),0) -> 0.0788 | L7: =IFERROR(COUNTIFS(Transaction_Data!$D$2:$D$5000,">="&$S$5,Transaction_Data!$D$2:$D$5000,"<"&$S$6,Transaction_Data!$H$2:$H$5000,$S$4,Transaction_Data!$J$2:$J$5000,"Pending")/COUNTIFS(Transaction_Data!$D$2:$D$5000,">="&$S$5,Transaction_Data!$D$2:$D$5000,"<"&$S$6,Transaction_Data!$H$2:$H$5000,$S$4),0) -> 0.0368 | N7: =IFERROR(COUNTIFS(Transaction_Data!$D$2:$D$5000,">="&$S$5,Transaction_Data!$D$2:$D$5000,"<"&$S$6,Transaction_Data!$H$2:$H$5000,$S$4,Transaction_Data!$K$2:$K$5000,"International")/COUNTIFS(Transaction_Data!$D$2:$D$5000,">="&$S$5,Transaction_Data!$D$2:$D$5000,"<"&$S$6,Transaction_Data!$H$2:$H$5000,$S$4),0) -> 0.4972
B58: Notes: Filters (yellow cells C4 / F4) drive every KPI, table and chart except where a heading says otherwise. Ranges read rows 2–5000 so appended data is picked up automatically. Category and month lists are typed in blue.
B59: CHART DATA & SUMMARY TABLES (all cells are live formulas on Transaction_Data; blue = hard-coded inputs/labels)
B60: A. Monthly trend (City filter applies; all years shown) | J60: D. By status
B61: Month start | C61: Month | D61: Transactions | E61: Volume (₹ Lakh) | F61: Success rate | J61: Status | K61: Transactions | L61: Share | M61: Volume (₹ Lakh)
B62: 45658 | C62: =TEXT(B62,"mmm-yy") -> Jan-25 | D62: =COUNTIFS(Transaction_Data!$D$2:$D$5000,">="&$B62,Transaction_Data!$D$2:$D$5000,"<"&EDATE($B62,1),Transaction_Data!$H$2:$H$5000,$S$4) -> 144 | E62: =SUMIFS(Transaction_Data!$F$2:$F$5000,Transaction_Data!$D$2:$D$5000,">="&$B62,Transaction_Data!$D$2:$D$5000,"<"&EDATE($B62,1),Transaction_Data!$H$2:$H$5000,$S$4)/100000 -> 151.9798 | F62: =IFERROR(COUNTIFS(Transaction_Data!$D$2:$D$5000,">="&$B62,Transaction_Data!$D$2:$D$5000,"<"&EDATE($B62,1),Transaction_Data!$H$2:$H$5000,$S$4,Transaction_Data!$J$2:$J$5000,"Success")/D62,0) -> 0.875 | J62: Success | K62: =COUNTIFS(Transaction_Data!$D$2:$D$5000,">="&$S$5,Transaction_Data!$D$2:$D$5000,"<"&$S$6,Transaction_Data!$H$2:$H$5000,$S$4,Transaction_Data!$J$2:$J$5000,$J62) -> 2211 | L62: =IFERROR(K62/COUNTIFS(Transaction_Data!$D$2:$D$5000,">="&$S$5,Transaction_Data!$D$2:$D$5000,"<"&$S$6,Transaction_Data!$H$2:$H$5000,$S$4),0) -> 0.8844 | M62: =SUMIFS(Transaction_Data!$F$2:$F$5000,Transaction_Data!$D$2:$D$5000,">="&$S$5,Transaction_Data!$D$2:$D$5000,"<"&$S$6,Transaction_Data!$H$2:$H$5000,$S$4,Transaction_Data!$J$2:$J$5000,$J62)/100000 -> 2196.6544
B63: 45689 | C63: =TEXT(B63,"mmm-yy") -> Feb-25 | D63: =COUNTIFS(Transaction_Data!$D$2:$D$5000,">="&$B63,Transaction_Data!$D$2:$D$5000,"<"&EDATE($B63,1),Transaction_Data!$H$2:$H$5000,$S$4) -> 108 | E63: =SUMIFS(Transaction_Data!$F$2:$F$5000,Transaction_Data!$D$2:$D$5000,">="&$B63,Transaction_Data!$D$2:$D$5000,"<"&EDATE($B63,1),Transaction_Data!$H$2:$H$5000,$S$4)/100000 -> 110.32463 | F63: =IFERROR(COUNTIFS(Transaction_Data!$D$2:$D$5000,">="&$B63,Transaction_Data!$D$2:$D$5000,"<"&EDATE($B63,1),Transaction_Data!$H$2:$H$5000,$S$4,Transaction_Data!$J$2:$J$5000,"Success")/D63,0) -> 0.89814815 | J63: Failed | K63: =COUNTIFS(Transaction_Data!$D$2:$D$5000,">="&$S$5,Transaction_Data!$D$2:$D$5000,"<"&$S$6,Transaction_Data!$H$2:$H$5000,$S$4,Transaction_Data!$J$2:$J$5000,$J63) -> 197 | L63: =IFERROR(K63/COUNTIFS(Transaction_Data!$D$2:$D$5000,">="&$S$5,Transaction_Data!$D$2:$D$5000,"<"&$S$6,Transaction_Data!$H$2:$H$5000,$S$4),0) -> 0.0788 | M63: =SUMIFS(Transaction_Data!$F$2:$F$5000,Transaction_Data!$D$2:$D$5000,">="&$S$5,Transaction_Data!$D$2:$D$5000,"<"&$S$6,Transaction_Data!$H$2:$H$5000,$S$4,Transaction_Data!$J$2:$J$5000,$J63)/100000 -> 186.22355
B64: 45717 | C64: =TEXT(B64,"mmm-yy") -> Mar-25 | D64: =COUNTIFS(Transaction_Data!$D$2:$D$5000,">="&$B64,Transaction_Data!$D$2:$D$5000,"<"&EDATE($B64,1),Transaction_Data!$H$2:$H$5000,$S$4) -> 127 | E64: =SUMIFS(Transaction_Data!$F$2:$F$5000,Transaction_Data!$D$2:$D$5000,">="&$B64,Transaction_Data!$D$2:$D$5000,"<"&EDATE($B64,1),Transaction_Data!$H$2:$H$5000,$S$4)/100000 -> 126.40894 | F64: =IFERROR(COUNTIFS(Transaction_Data!$D$2:$D$5000,">="&$B64,Transaction_Data!$D$2:$D$5000,"<"&EDATE($B64,1),Transaction_Data!$H$2:$H$5000,$S$4,Transaction_Data!$J$2:$J$5000,"Success")/D64,0) -> 0.92913386 | J64: Pending | K64: =COUNTIFS(Transaction_Data!$D$2:$D$5000,">="&$S$5,Transaction_Data!$D$2:$D$5000,"<"&$S$6,Transaction_Data!$H$2:$H$5000,$S$4,Transaction_Data!$J$2:$J$5000,$J64) -> 92 | L64: =IFERROR(K64/COUNTIFS(Transaction_Data!$D$2:$D$5000,">="&$S$5,Transaction_Data!$D$2:$D$5000,"<"&$S$6,Transaction_Data!$H$2:$H$5000,$S$4),0) -> 0.0368 | M64: =SUMIFS(Transaction_Data!$F$2:$F$5000,Transaction_Data!$D$2:$D$5000,">="&$S$5,Transaction_Data!$D$2:$D$5000,"<"&$S$6,Transaction_Data!$H$2:$H$5000,$S$4,Transaction_Data!$J$2:$J$5000,$J64)/100000 -> 101.11951
B65: 45748 | C65: =TEXT(B65,"mmm-yy") -> Apr-25 | D65: =COUNTIFS(Transaction_Data!$D$2:$D$5000,">="&$B65,Transaction_Data!$D$2:$D$5000,"<"&EDATE($B65,1),Transaction_Data!$H$2:$H$5000,$S$4) -> 104 | E65: =SUMIFS(Transaction_Data!$F$2:$F$5000,Transaction_Data!$D$2:$D$5000,">="&$B65,Transaction_Data!$D$2:$D$5000,"<"&EDATE($B65,1),Transaction_Data!$H$2:$H$5000,$S$4)/100000 -> 106.93266 | F65: =IFERROR(COUNTIFS(Transaction_Data!$D$2:$D$5000,">="&$B65,Transaction_Data!$D$2:$D$5000,"<"&EDATE($B65,1),Transaction_Data!$H$2:$H$5000,$S$4,Transaction_Data!$J$2:$J$5000,"Success")/D65,0) -> 0.93269231
B66: 45778 | C66: =TEXT(B66,"mmm-yy") -> May-25 | D66: =COUNTIFS(Transaction_Data!$D$2:$D$5000,">="&$B66,Transaction_Data!$D$2:$D$5000,"<"&EDATE($B66,1),Transaction_Data!$H$2:$H$5000,$S$4) -> 143 | E66: =SUMIFS(Transaction_Data!$F$2:$F$5000,Transaction_Data!$D$2:$D$5000,">="&$B66,Transaction_Data!$D$2:$D$5000,"<"&EDATE($B66,1),Transaction_Data!$H$2:$H$5000,$S$4)/100000 -> 141.77054 | F66: =IFERROR(COUNTIFS(Transaction_Data!$D$2:$D$5000,">="&$B66,Transaction_Data!$D$2:$D$5000,"<"&EDATE($B66,1),Transaction_Data!$H$2:$H$5000,$S$4,Transaction_Data!$J$2:$J$5000,"Success")/D66,0) -> 0.81818182
B67: 45809 | C67: =TEXT(B67,"mmm-yy") -> Jun-25 | D67: =COUNTIFS(Transaction_Data!$D$2:$D$5000,">="&$B67,Transaction_Data!$D$2:$D$5000,"<"&EDATE($B67,1),Transaction_Data!$H$2:$H$5000,$S$4) -> 124 | E67: =SUMIFS(Transaction_Data!$F$2:$F$5000,Transaction_Data!$D$2:$D$5000,">="&$B67,Transaction_Data!$D$2:$D$5000,"<"&EDATE($B67,1),Transaction_Data!$H$2:$H$5000,$S$4)/100000 -> 125.39355 | F67: =IFERROR(COUNTIFS(Transaction_Data!$D$2:$D$5000,">="&$B67,Transaction_Data!$D$2:$D$5000,"<"&EDATE($B67,1),Transaction_Data!$H$2:$H$5000,$S$4,Transaction_Data!$J$2:$J$5000,"Success")/D67,0) -> 0.88709677 | J67: E. Domestic vs International
B68: 45839 | C68: =TEXT(B68,"mmm-yy") -> Jul-25 | D68: =COUNTIFS(Transaction_Data!$D$2:$D$5000,">="&$B68,Transaction_Data!$D$2:$D$5000,"<"&EDATE($B68,1),Transaction_Data!$H$2:$H$5000,$S$4) -> 124 | E68: =SUMIFS(Transaction_Data!$F$2:$F$5000,Transaction_Data!$D$2:$D$5000,">="&$B68,Transaction_Data!$D$2:$D$5000,"<"&EDATE($B68,1),Transaction_Data!$H$2:$H$5000,$S$4)/100000 -> 129.06501 | F68: =IFERROR(COUNTIFS(Transaction_Data!$D$2:$D$5000,">="&$B68,Transaction_Data!$D$2:$D$5000,"<"&EDATE($B68,1),Transaction_Data!$H$2:$H$5000,$S$4,Transaction_Data!$J$2:$J$5000,"Success")/D68,0) -> 0.85483871 | J68: Geography | K68: Transactions | L68: Share | M68: Volume (₹ Lakh)
B69: 45870 | C69: =TEXT(B69,"mmm-yy") -> Aug-25 | D69: =COUNTIFS(Transaction_Data!$D$2:$D$5000,">="&$B69,Transaction_Data!$D$2:$D$5000,"<"&EDATE($B69,1),Transaction_Data!$H$2:$H$5000,$S$4) -> 119 | E69: =SUMIFS(Transaction_Data!$F$2:$F$5000,Transaction_Data!$D$2:$D$5000,">="&$B69,Transaction_Data!$D$2:$D$5000,"<"&EDATE($B69,1),Transaction_Data!$H$2:$H$5000,$S$4)/100000 -> 117.41928 | F69: =IFERROR(COUNTIFS(Transaction_Data!$D$2:$D$5000,">="&$B69,Transaction_Data!$D$2:$D$5000,"<"&EDATE($B69,1),Transaction_Data!$H$2:$H$5000,$S$4,Transaction_Data!$J$2:$J$5000,"Success")/D69,0) -> 0.85714286 | J69: Domestic | K69: =COUNTIFS(Transaction_Data!$D$2:$D$5000,">="&$S$5,Transaction_Data!$D$2:$D$5000,"<"&$S$6,Transaction_Data!$H$2:$H$5000,$S$4,Transaction_Data!$K$2:$K$5000,$J69) -> 1257 | L69: =IFERROR(K69/COUNTIFS(Transaction_Data!$D$2:$D$5000,">="&$S$5,Transaction_Data!$D$2:$D$5000,"<"&$S$6,Transaction_Data!$H$2:$H$5000,$S$4),0) -> 0.5028 | M69: =SUMIFS(Transaction_Data!$F$2:$F$5000,Transaction_Data!$D$2:$D$5000,">="&$S$5,Transaction_Data!$D$2:$D$5000,"<"&$S$6,Transaction_Data!$H$2:$H$5000,$S$4,Transaction_Data!$K$2:$K$5000,$J69)/100000 -> 1253.0316
B70: 45901 | C70: =TEXT(B70,"mmm-yy") -> Sep-25 | D70: =COUNTIFS(Transaction_Data!$D$2:$D$5000,">="&$B70,Transaction_Data!$D$2:$D$5000,"<"&EDATE($B70,1),Transaction_Data!$H$2:$H$5000,$S$4) -> 114 | E70: =SUMIFS(Transaction_Data!$F$2:$F$5000,Transaction_Data!$D$2:$D$5000,">="&$B70,Transaction_Data!$D$2:$D$5000,"<"&EDATE($B70,1),Transaction_Data!$H$2:$H$5000,$S$4)/100000 -> 105.72873 | F70: =IFERROR(COUNTIFS(Transaction_Data!$D$2:$D$5000,">="&$B70,Transaction_Data!$D$2:$D$5000,"<"&EDATE($B70,1),Transaction_Data!$H$2:$H$5000,$S$4,Transaction_Data!$J$2:$J$5000,"Success")/D70,0) -> 0.90350877 | J70: International | K70: =COUNTIFS(Transaction_Data!$D$2:$D$5000,">="&$S$5,Transaction_Data!$D$2:$D$5000,"<"&$S$6,Transaction_Data!$H$2:$H$5000,$S$4,Transaction_Data!$K$2:$K$5000,$J70) -> 1243 | L70: =IFERROR(K70/COUNTIFS(Transaction_Data!$D$2:$D$5000,">="&$S$5,Transaction_Data!$D$2:$D$5000,"<"&$S$6,Transaction_Data!$H$2:$H$5000,$S$4),0) -> 0.4972 | M70: =SUMIFS(Transaction_Data!$F$2:$F$5000,Transaction_Data!$D$2:$D$5000,">="&$S$5,Transaction_Data!$D$2:$D$5000,"<"&$S$6,Transaction_Data!$H$2:$H$5000,$S$4,Transaction_Data!$K$2:$K$5000,$J70)/100000 -> 1230.9658
B71: 45931 | C71: =TEXT(B71,"mmm-yy") -> Oct-25 | D71: =COUNTIFS(Transaction_Data!$D$2:$D$5000,">="&$B71,Transaction_Data!$D$2:$D$5000,"<"&EDATE($B71,1),Transaction_Data!$H$2:$H$5000,$S$4) -> 131 | E71: =SUMIFS(Transaction_Data!$F$2:$F$5000,Transaction_Data!$D$2:$D$5000,">="&$B71,Transaction_Data!$D$2:$D$5000,"<"&EDATE($B71,1),Transaction_Data!$H$2:$H$5000,$S$4)/100000 -> 134.92248 | F71: =IFERROR(COUNTIFS(Transaction_Data!$D$2:$D$5000,">="&$B71,Transaction_Data!$D$2:$D$5000,"<"&EDATE($B71,1),Transaction_Data!$H$2:$H$5000,$S$4,Transaction_Data!$J$2:$J$5000,"Success")/D71,0) -> 0.85496183
B72: 45962 | C72: =TEXT(B72,"mmm-yy") -> Nov-25 | D72: =COUNTIFS(Transaction_Data!$D$2:$D$5000,">="&$B72,Transaction_Data!$D$2:$D$5000,"<"&EDATE($B72,1),Transaction_Data!$H$2:$H$5000,$S$4) -> 105 | E72: =SUMIFS(Transaction_Data!$F$2:$F$5000,Transaction_Data!$D$2:$D$5000,">="&$B72,Transaction_Data!$D$2:$D$5000,"<"&EDATE($B72,1),Transaction_Data!$H$2:$H$5000,$S$4)/100000 -> 92.928771 | F72: =IFERROR(COUNTIFS(Transaction_Data!$D$2:$D$5000,">="&$B72,Transaction_Data!$D$2:$D$5000,"<"&EDATE($B72,1),Transaction_Data!$H$2:$H$5000,$S$4,Transaction_Data!$J$2:$J$5000,"Success")/D72,0) -> 0.8952381
B73: 45992 | C73: =TEXT(B73,"mmm-yy") -> Dec-25 | D73: =COUNTIFS(Transaction_Data!$D$2:$D$5000,">="&$B73,Transaction_Data!$D$2:$D$5000,"<"&EDATE($B73,1),Transaction_Data!$H$2:$H$5000,$S$4) -> 129 | E73: =SUMIFS(Transaction_Data!$F$2:$F$5000,Transaction_Data!$D$2:$D$5000,">="&$B73,Transaction_Data!$D$2:$D$5000,"<"&EDATE($B73,1),Transaction_Data!$H$2:$H$5000,$S$4)/100000 -> 128.43557 | F73: =IFERROR(COUNTIFS(Transaction_Data!$D$2:$D$5000,">="&$B73,Transaction_Data!$D$2:$D$5000,"<"&EDATE($B73,1),Transaction_Data!$H$2:$H$5000,$S$4,Transaction_Data!$J$2:$J$5000,"Success")/D73,0) -> 0.80620155 | J73: F. By city (Year filter only)
B74: 46023 | C74: =TEXT(B74,"mmm-yy") -> Jan-26 | D74: =COUNTIFS(Transaction_Data!$D$2:$D$5000,">="&$B74,Transaction_Data!$D$2:$D$5000,"<"&EDATE($B74,1),Transaction_Data!$H$2:$H$5000,$S$4) -> 131 | E74: =SUMIFS(Transaction_Data!$F$2:$F$5000,Transaction_Data!$D$2:$D$5000,">="&$B74,Transaction_Data!$D$2:$D$5000,"<"&EDATE($B74,1),Transaction_Data!$H$2:$H$5000,$S$4)/100000 -> 126.68781 | F74: =IFERROR(COUNTIFS(Transaction_Data!$D$2:$D$5000,">="&$B74,Transaction_Data!$D$2:$D$5000,"<"&EDATE($B74,1),Transaction_Data!$H$2:$H$5000,$S$4,Transaction_Data!$J$2:$J$5000,"Success")/D74,0) -> 0.91603053 | J74: City | K74: Transactions | L74: Volume (₹ Lakh) | M74: Avg ticket (₹) | N74: Success %
B75: 46054 | C75: =TEXT(B75,"mmm-yy") -> Feb-26 | D75: =COUNTIFS(Transaction_Data!$D$2:$D$5000,">="&$B75,Transaction_Data!$D$2:$D$5000,"<"&EDATE($B75,1),Transaction_Data!$H$2:$H$5000,$S$4) -> 88 | E75: =SUMIFS(Transaction_Data!$F$2:$F$5000,Transaction_Data!$D$2:$D$5000,">="&$B75,Transaction_Data!$D$2:$D$5000,"<"&EDATE($B75,1),Transaction_Data!$H$2:$H$5000,$S$4)/100000 -> 90.259747 | F75: =IFERROR(COUNTIFS(Transaction_Data!$D$2:$D$5000,">="&$B75,Transaction_Data!$D$2:$D$5000,"<"&EDATE($B75,1),Transaction_Data!$H$2:$H$5000,$S$4,Transaction_Data!$J$2:$J$5000,"Success")/D75,0) -> 0.875 | J75: Bengaluru | K75: =COUNTIFS(Transaction_Data!$D$2:$D$5000,">="&$S$5,Transaction_Data!$D$2:$D$5000,"<"&$S$6,Transaction_Data!$H$2:$H$5000,$J75) -> 283 | L75: =SUMIFS(Transaction_Data!$F$2:$F$5000,Transaction_Data!$D$2:$D$5000,">="&$S$5,Transaction_Data!$D$2:$D$5000,"<"&$S$6,Transaction_Data!$H$2:$H$5000,$J75)/100000 -> 281.5023 | M75: =IFERROR(L75*100000/K75,0) -> 99470.776 | N75: =IFERROR(COUNTIFS(Transaction_Data!$D$2:$D$5000,">="&$S$5,Transaction_Data!$D$2:$D$5000,"<"&$S$6,Transaction_Data!$H$2:$H$5000,$J75,Transaction_Data!$J$2:$J$5000,"Success")/K75,0) -> 0.8869258
B76: 46082 | C76: =TEXT(B76,"mmm-yy") -> Mar-26 | D76: =COUNTIFS(Transaction_Data!$D$2:$D$5000,">="&$B76,Transaction_Data!$D$2:$D$5000,"<"&EDATE($B76,1),Transaction_Data!$H$2:$H$5000,$S$4) -> 121 | E76: =SUMIFS(Transaction_Data!$F$2:$F$5000,Transaction_Data!$D$2:$D$5000,">="&$B76,Transaction_Data!$D$2:$D$5000,"<"&EDATE($B76,1),Transaction_Data!$H$2:$H$5000,$S$4)/100000 -> 121.37357 | F76: =IFERROR(COUNTIFS(Transaction_Data!$D$2:$D$5000,">="&$B76,Transaction_Data!$D$2:$D$5000,"<"&EDATE($B76,1),Transaction_Data!$H$2:$H$5000,$S$4,Transaction_Data!$J$2:$J$5000,"Success")/D76,0) -> 0.88429752 | J76: Chennai | K76: =COUNTIFS(Transaction_Data!$D$2:$D$5000,">="&$S$5,Transaction_Data!$D$2:$D$5000,"<"&$S$6,Transaction_Data!$H$2:$H$5000,$J76) -> 225 | L76: =SUMIFS(Transaction_Data!$F$2:$F$5000,Transaction_Data!$D$2:$D$5000,">="&$S$5,Transaction_Data!$D$2:$D$5000,"<"&$S$6,Transaction_Data!$H$2:$H$5000,$J76)/100000 -> 225.53121 | M76: =IFERROR(L76*100000/K76,0) -> 100236.09 | N76: =IFERROR(COUNTIFS(Transaction_Data!$D$2:$D$5000,">="&$S$5,Transaction_Data!$D$2:$D$5000,"<"&$S$6,Transaction_Data!$H$2:$H$5000,$J76,Transaction_Data!$J$2:$J$5000,"Success")/K76,0) -> 0.89777778
B77: 46113 | C77: =TEXT(B77,"mmm-yy") -> Apr-26 | D77: =COUNTIFS(Transaction_Data!$D$2:$D$5000,">="&$B77,Transaction_Data!$D$2:$D$5000,"<"&EDATE($B77,1),Transaction_Data!$H$2:$H$5000,$S$4) -> 107 | E77: =SUMIFS(Transaction_Data!$F$2:$F$5000,Transaction_Data!$D$2:$D$5000,">="&$B77,Transaction_Data!$D$2:$D$5000,"<"&EDATE($B77,1),Transaction_Data!$H$2:$H$5000,$S$4)/100000 -> 105.36077 | F77: =IFERROR(COUNTIFS(Transaction_Data!$D$2:$D$5000,">="&$B77,Transaction_Data!$D$2:$D$5000,"<"&EDATE($B77,1),Transaction_Data!$H$2:$H$5000,$S$4,Transaction_Data!$J$2:$J$5000,"Success")/D77,0) -> 0.90654206 | J77: Delhi | K77: =COUNTIFS(Transaction_Data!$D$2:$D$5000,">="&$S$5,Transaction_Data!$D$2:$D$5000,"<"&$S$6,Transaction_Data!$H$2:$H$5000,$J77) -> 203 | L77: =SUMIFS(Transaction_Data!$F$2:$F$5000,Transaction_Data!$D$2:$D$5000,">="&$S$5,Transaction_Data!$D$2:$D$5000,"<"&$S$6,Transaction_Data!$H$2:$H$5000,$J77)/100000 -> 222.70211 | M77: =IFERROR(L77*100000/K77,0) -> 109705.47 | N77: =IFERROR(COUNTIFS(Transaction_Data!$D$2:$D$5000,">="&$S$5,Transaction_Data!$D$2:$D$5000,"<"&$S$6,Transaction_Data!$H$2:$H$5000,$J77,Transaction_Data!$J$2:$J$5000,"Success")/K77,0) -> 0.87684729
B78: 46143 | C78: =TEXT(B78,"mmm-yy") -> May-26 | D78: =COUNTIFS(Transaction_Data!$D$2:$D$5000,">="&$B78,Transaction_Data!$D$2:$D$5000,"<"&EDATE($B78,1),Transaction_Data!$H$2:$H$5000,$S$4) -> 116 | E78: =SUMIFS(Transaction_Data!$F$2:$F$5000,Transaction_Data!$D$2:$D$5000,">="&$B78,Transaction_Data!$D$2:$D$5000,"<"&EDATE($B78,1),Transaction_Data!$H$2:$H$5000,$S$4)/100000 -> 105.42411 | F78: =IFERROR(COUNTIFS(Transaction_Data!$D$2:$D$5000,">="&$B78,Transaction_Data!$D$2:$D$5000,"<"&EDATE($B78,1),Transaction_Data!$H$2:$H$5000,$S$4,Transaction_Data!$J$2:$J$5000,"Success")/D78,0) -> 0.9137931 | J78: Hyderabad | K78: =COUNTIFS(Transaction_Data!$D$2:$D$5000,">="&$S$5,Transaction_Data!$D$2:$D$5000,"<"&$S$6,Transaction_Data!$H$2:$H$5000,$J78) -> 202 | L78: =SUMIFS(Transaction_Data!$F$2:$F$5000,Transaction_Data!$D$2:$D$5000,">="&$S$5,Transaction_Data!$D$2:$D$5000,"<"&$S$6,Transaction_Data!$H$2:$H$5000,$J78)/100000 -> 187.39719 | M78: =IFERROR(L78*100000/K78,0) -> 92770.888 | N78: =IFERROR(COUNTIFS(Transaction_Data!$D$2:$D$5000,">="&$S$5,Transaction_Data!$D$2:$D$5000,"<"&$S$6,Transaction_Data!$H$2:$H$5000,$J78,Transaction_Data!$J$2:$J$5000,"Success")/K78,0) -> 0.8960396
B79: 46174 | C79: =TEXT(B79,"mmm-yy") -> Jun-26 | D79: =COUNTIFS(Transaction_Data!$D$2:$D$5000,">="&$B79,Transaction_Data!$D$2:$D$5000,"<"&EDATE($B79,1),Transaction_Data!$H$2:$H$5000,$S$4) -> 115 | E79: =SUMIFS(Transaction_Data!$F$2:$F$5000,Transaction_Data!$D$2:$D$5000,">="&$B79,Transaction_Data!$D$2:$D$5000,"<"&EDATE($B79,1),Transaction_Data!$H$2:$H$5000,$S$4)/100000 -> 117.14138 | F79: =IFERROR(COUNTIFS(Transaction_Data!$D$2:$D$5000,">="&$B79,Transaction_Data!$D$2:$D$5000,"<"&EDATE($B79,1),Transaction_Data!$H$2:$H$5000,$S$4,Transaction_Data!$J$2:$J$5000,"Success")/D79,0) -> 0.92173913 | J79: Jaipur | K79: =COUNTIFS(Transaction_Data!$D$2:$D$5000,">="&$S$5,Transaction_Data!$D$2:$D$5000,"<"&$S$6,Transaction_Data!$H$2:$H$5000,$J79) -> 309 | L79: =SUMIFS(Transaction_Data!$F$2:$F$5000,Transaction_Data!$D$2:$D$5000,">="&$S$5,Transaction_Data!$D$2:$D$5000,"<"&$S$6,Transaction_Data!$H$2:$H$5000,$J79)/100000 -> 307.26009 | M79: =IFERROR(L79*100000/K79,0) -> 99436.924 | N79: =IFERROR(COUNTIFS(Transaction_Data!$D$2:$D$5000,">="&$S$5,Transaction_Data!$D$2:$D$5000,"<"&$S$6,Transaction_Data!$H$2:$H$5000,$J79,Transaction_Data!$J$2:$J$5000,"Success")/K79,0) -> 0.91262136
B80: 46204 | C80: =TEXT(B80,"mmm-yy") -> Jul-26 | D80: =COUNTIFS(Transaction_Data!$D$2:$D$5000,">="&$B80,Transaction_Data!$D$2:$D$5000,"<"&EDATE($B80,1),Transaction_Data!$H$2:$H$5000,$S$4) -> 107 | E80: =SUMIFS(Transaction_Data!$F$2:$F$5000,Transaction_Data!$D$2:$D$5000,">="&$B80,Transaction_Data!$D$2:$D$5000,"<"&EDATE($B80,1),Transaction_Data!$H$2:$H$5000,$S$4)/100000 -> 111.51138 | F80: =IFERROR(COUNTIFS(Transaction_Data!$D$2:$D$5000,">="&$B80,Transaction_Data!$D$2:$D$5000,"<"&EDATE($B80,1),Transaction_Data!$H$2:$H$5000,$S$4,Transaction_Data!$J$2:$J$5000,"Success")/D80,0) -> 0.89719626 | J80: Kolkata | K80: =COUNTIFS(Transaction_Data!$D$2:$D$5000,">="&$S$5,Transaction_Data!$D$2:$D$5000,"<"&$S$6,Transaction_Data!$H$2:$H$5000,$J80) -> 256 | L80: =SUMIFS(Transaction_Data!$F$2:$F$5000,Transaction_Data!$D$2:$D$5000,">="&$S$5,Transaction_Data!$D$2:$D$5000,"<"&$S$6,Transaction_Data!$H$2:$H$5000,$J80)/100000 -> 248.2912 | M80: =IFERROR(L80*100000/K80,0) -> 96988.749 | N80: =IFERROR(COUNTIFS(Transaction_Data!$D$2:$D$5000,">="&$S$5,Transaction_Data!$D$2:$D$5000,"<"&$S$6,Transaction_Data!$H$2:$H$5000,$J80,Transaction_Data!$J$2:$J$5000,"Success")/K80,0) -> 0.890625
B81: 46235 | C81: =TEXT(B81,"mmm-yy") -> Aug-26 | D81: =COUNTIFS(Transaction_Data!$D$2:$D$5000,">="&$B81,Transaction_Data!$D$2:$D$5000,"<"&EDATE($B81,1),Transaction_Data!$H$2:$H$5000,$S$4) -> 125 | E81: =SUMIFS(Transaction_Data!$F$2:$F$5000,Transaction_Data!$D$2:$D$5000,">="&$B81,Transaction_Data!$D$2:$D$5000,"<"&EDATE($B81,1),Transaction_Data!$H$2:$H$5000,$S$4)/100000 -> 126.61122 | F81: =IFERROR(COUNTIFS(Transaction_Data!$D$2:$D$5000,">="&$B81,Transaction_Data!$D$2:$D$5000,"<"&EDATE($B81,1),Transaction_Data!$H$2:$H$5000,$S$4,Transaction_Data!$J$2:$J$5000,"Success")/D81,0) -> 0.848 | J81: Lucknow | K81: =COUNTIFS(Transaction_Data!$D$2:$D$5000,">="&$S$5,Transaction_Data!$D$2:$D$5000,"<"&$S$6,Transaction_Data!$H$2:$H$5000,$J81) -> 244 | L81: =SUMIFS(Transaction_Data!$F$2:$F$5000,Transaction_Data!$D$2:$D$5000,">="&$S$5,Transaction_Data!$D$2:$D$5000,"<"&$S$6,Transaction_Data!$H$2:$H$5000,$J81)/100000 -> 241.19114 | M81: =IFERROR(L81*100000/K81,0) -> 98848.826 | N81: =IFERROR(COUNTIFS(Transaction_Data!$D$2:$D$5000,">="&$S$5,Transaction_Data!$D$2:$D$5000,"<"&$S$6,Transaction_Data!$H$2:$H$5000,$J81,Transaction_Data!$J$2:$J$5000,"Success")/K81,0) -> 0.84016393
B82: 46266 | C82: =TEXT(B82,"mmm-yy") -> Sep-26 | D82: =COUNTIFS(Transaction_Data!$D$2:$D$5000,">="&$B82,Transaction_Data!$D$2:$D$5000,"<"&EDATE($B82,1),Transaction_Data!$H$2:$H$5000,$S$4) -> 118 | E82: =SUMIFS(Transaction_Data!$F$2:$F$5000,Transaction_Data!$D$2:$D$5000,">="&$B82,Transaction_Data!$D$2:$D$5000,"<"&EDATE($B82,1),Transaction_Data!$H$2:$H$5000,$S$4)/100000 -> 108.31745 | F82: =IFERROR(COUNTIFS(Transaction_Data!$D$2:$D$5000,">="&$B82,Transaction_Data!$D$2:$D$5000,"<"&EDATE($B82,1),Transaction_Data!$H$2:$H$5000,$S$4,Transaction_Data!$J$2:$J$5000,"Success")/D82,0) -> 0.93220339 | J82: Mumbai | K82: =COUNTIFS(Transaction_Data!$D$2:$D$5000,">="&$S$5,Transaction_Data!$D$2:$D$5000,"<"&$S$6,Transaction_Data!$H$2:$H$5000,$J82) -> 258 | L82: =SUMIFS(Transaction_Data!$F$2:$F$5000,Transaction_Data!$D$2:$D$5000,">="&$S$5,Transaction_Data!$D$2:$D$5000,"<"&$S$6,Transaction_Data!$H$2:$H$5000,$J82)/100000 -> 266.85729 | M82: =IFERROR(L82*100000/K82,0) -> 103433.06 | N82: =IFERROR(COUNTIFS(Transaction_Data!$D$2:$D$5000,">="&$S$5,Transaction_Data!$D$2:$D$5000,"<"&$S$6,Transaction_Data!$H$2:$H$5000,$J82,Transaction_Data!$J$2:$J$5000,"Success")/K82,0) -> 0.85271318
J83: Noida | K83: =COUNTIFS(Transaction_Data!$D$2:$D$5000,">="&$S$5,Transaction_Data!$D$2:$D$5000,"<"&$S$6,Transaction_Data!$H$2:$H$5000,$J83) -> 280 | L83: =SUMIFS(Transaction_Data!$F$2:$F$5000,Transaction_Data!$D$2:$D$5000,">="&$S$5,Transaction_Data!$D$2:$D$5000,"<"&$S$6,Transaction_Data!$H$2:$H$5000,$J83)/100000 -> 271.32773 | M83: =IFERROR(L83*100000/K83,0) -> 96902.76 | N83: =IFERROR(COUNTIFS(Transaction_Data!$D$2:$D$5000,">="&$S$5,Transaction_Data!$D$2:$D$5000,"<"&$S$6,Transaction_Data!$H$2:$H$5000,$J83,Transaction_Data!$J$2:$J$5000,"Success")/K83,0) -> 0.89285714
J84: Pune | K84: =COUNTIFS(Transaction_Data!$D$2:$D$5000,">="&$S$5,Transaction_Data!$D$2:$D$5000,"<"&$S$6,Transaction_Data!$H$2:$H$5000,$J84) -> 240 | L84: =SUMIFS(Transaction_Data!$F$2:$F$5000,Transaction_Data!$D$2:$D$5000,">="&$S$5,Transaction_Data!$D$2:$D$5000,"<"&$S$6,Transaction_Data!$H$2:$H$5000,$J84)/100000 -> 231.93717 | M84: =IFERROR(L84*100000/K84,0) -> 96640.487 | N84: =IFERROR(COUNTIFS(Transaction_Data!$D$2:$D$5000,">="&$S$5,Transaction_Data!$D$2:$D$5000,"<"&$S$6,Transaction_Data!$H$2:$H$5000,$J84,Transaction_Data!$J$2:$J$5000,"Success")/K84,0) -> 0.89166667
B85: B. By transaction type
B86: Transaction type | C86: Transactions | D86: Volume (₹ Lakh) | E86: Avg ticket (₹) | F86: Success % | G86: Failed % | H86: Pending %
B87: ATM | C87: =COUNTIFS(Transaction_Data!$D$2:$D$5000,">="&$S$5,Transaction_Data!$D$2:$D$5000,"<"&$S$6,Transaction_Data!$H$2:$H$5000,$S$4,Transaction_Data!$E$2:$E$5000,$B87) -> 385 | D87: =SUMIFS(Transaction_Data!$F$2:$F$5000,Transaction_Data!$D$2:$D$5000,">="&$S$5,Transaction_Data!$D$2:$D$5000,"<"&$S$6,Transaction_Data!$H$2:$H$5000,$S$4,Transaction_Data!$E$2:$E$5000,$B87)/100000 -> 368.83173 | E87: =IFERROR(SUMIFS(Transaction_Data!$F$2:$F$5000,Transaction_Data!$D$2:$D$5000,">="&$S$5,Transaction_Data!$D$2:$D$5000,"<"&$S$6,Transaction_Data!$H$2:$H$5000,$S$4,Transaction_Data!$E$2:$E$5000,$B87)/C87,0) -> 95800.45 | F87: =IFERROR(COUNTIFS(Transaction_Data!$D$2:$D$5000,">="&$S$5,Transaction_Data!$D$2:$D$5000,"<"&$S$6,Transaction_Data!$H$2:$H$5000,$S$4,Transaction_Data!$E$2:$E$5000,$B87,Transaction_Data!$J$2:$J$5000,"Success")/C87,0) -> 0.87272727 | G87: =IFERROR(COUNTIFS(Transaction_Data!$D$2:$D$5000,">="&$S$5,Transaction_Data!$D$2:$D$5000,"<"&$S$6,Transaction_Data!$H$2:$H$5000,$S$4,Transaction_Data!$E$2:$E$5000,$B87,Transaction_Data!$J$2:$J$5000,"Failed")/C87,0) -> 0.096103896 | H87: =IFERROR(COUNTIFS(Transaction_Data!$D$2:$D$5000,">="&$S$5,Transaction_Data!$D$2:$D$5000,"<"&$S$6,Transaction_Data!$H$2:$H$5000,$S$4,Transaction_Data!$E$2:$E$5000,$B87,Transaction_Data!$J$2:$J$5000,"Pending")/C87,0) -> 0.031168831 | J87: G. Top 10 branches by volume (respects City & Year filters)
B88: Card | C88: =COUNTIFS(Transaction_Data!$D$2:$D$5000,">="&$S$5,Transaction_Data!$D$2:$D$5000,"<"&$S$6,Transaction_Data!$H$2:$H$5000,$S$4,Transaction_Data!$E$2:$E$5000,$B88) -> 345 | D88: =SUMIFS(Transaction_Data!$F$2:$F$5000,Transaction_Data!$D$2:$D$5000,">="&$S$5,Transaction_Data!$D$2:$D$5000,"<"&$S$6,Transaction_Data!$H$2:$H$5000,$S$4,Transaction_Data!$E$2:$E$5000,$B88)/100000 -> 333.13387 | E88: =IFERROR(SUMIFS(Transaction_Data!$F$2:$F$5000,Transaction_Data!$D$2:$D$5000,">="&$S$5,Transaction_Data!$D$2:$D$5000,"<"&$S$6,Transaction_Data!$H$2:$H$5000,$S$4,Transaction_Data!$E$2:$E$5000,$B88)/C88,0) -> 96560.543 | F88: =IFERROR(COUNTIFS(Transaction_Data!$D$2:$D$5000,">="&$S$5,Transaction_Data!$D$2:$D$5000,"<"&$S$6,Transaction_Data!$H$2:$H$5000,$S$4,Transaction_Data!$E$2:$E$5000,$B88,Transaction_Data!$J$2:$J$5000,"Success")/C88,0) -> 0.88115942 | G88: =IFERROR(COUNTIFS(Transaction_Data!$D$2:$D$5000,">="&$S$5,Transaction_Data!$D$2:$D$5000,"<"&$S$6,Transaction_Data!$H$2:$H$5000,$S$4,Transaction_Data!$E$2:$E$5000,$B88,Transaction_Data!$J$2:$J$5000,"Failed")/C88,0) -> 0.075362319 | H88: =IFERROR(COUNTIFS(Transaction_Data!$D$2:$D$5000,">="&$S$5,Transaction_Data!$D$2:$D$5000,"<"&$S$6,Transaction_Data!$H$2:$H$5000,$S$4,Transaction_Data!$E$2:$E$5000,$B88,Transaction_Data!$J$2:$J$5000,"Pending")/C88,0) -> 0.043478261 | J88: Rank | K88: Branch | L88: City | M88: Transactions | N88: Volume (₹ Lakh)
B89: Cash Deposit | C89: =COUNTIFS(Transaction_Data!$D$2:$D$5000,">="&$S$5,Transaction_Data!$D$2:$D$5000,"<"&$S$6,Transaction_Data!$H$2:$H$5000,$S$4,Transaction_Data!$E$2:$E$5000,$B89) -> 321 | D89: =SUMIFS(Transaction_Data!$F$2:$F$5000,Transaction_Data!$D$2:$D$5000,">="&$S$5,Transaction_Data!$D$2:$D$5000,"<"&$S$6,Transaction_Data!$H$2:$H$5000,$S$4,Transaction_Data!$E$2:$E$5000,$B89)/100000 -> 321.07789 | E89: =IFERROR(SUMIFS(Transaction_Data!$F$2:$F$5000,Transaction_Data!$D$2:$D$5000,">="&$S$5,Transaction_Data!$D$2:$D$5000,"<"&$S$6,Transaction_Data!$H$2:$H$5000,$S$4,Transaction_Data!$E$2:$E$5000,$B89)/C89,0) -> 100024.26 | F89: =IFERROR(COUNTIFS(Transaction_Data!$D$2:$D$5000,">="&$S$5,Transaction_Data!$D$2:$D$5000,"<"&$S$6,Transaction_Data!$H$2:$H$5000,$S$4,Transaction_Data!$E$2:$E$5000,$B89,Transaction_Data!$J$2:$J$5000,"Success")/C89,0) -> 0.89719626 | G89: =IFERROR(COUNTIFS(Transaction_Data!$D$2:$D$5000,">="&$S$5,Transaction_Data!$D$2:$D$5000,"<"&$S$6,Transaction_Data!$H$2:$H$5000,$S$4,Transaction_Data!$E$2:$E$5000,$B89,Transaction_Data!$J$2:$J$5000,"Failed")/C89,0) -> 0.062305296 | H89: =IFERROR(COUNTIFS(Transaction_Data!$D$2:$D$5000,">="&$S$5,Transaction_Data!$D$2:$D$5000,"<"&$S$6,Transaction_Data!$H$2:$H$5000,$S$4,Transaction_Data!$E$2:$E$5000,$B89,Transaction_Data!$J$2:$J$5000,"Pending")/C89,0) -> 0.040498442 | J89: 1 | K89: =INDEX($J$103:$J$132,MATCH(LARGE($M$103:$M$132,$J89),$M$103:$M$132,0)) -> Malviya Nagar | L89: =INDEX($K$103:$K$132,MATCH(LARGE($M$103:$M$132,$J89),$M$103:$M$132,0)) -> Jaipur | M89: =INDEX($L$103:$L$132,MATCH(LARGE($M$103:$M$132,$J89),$M$103:$M$132,0)) -> 126 | N89: =INDEX($M$103:$M$132,MATCH(LARGE($M$103:$M$132,$J89),$M$103:$M$132,0)) -> 119.7366
B90: Cash Withdrawal | C90: =COUNTIFS(Transaction_Data!$D$2:$D$5000,">="&$S$5,Transaction_Data!$D$2:$D$5000,"<"&$S$6,Transaction_Data!$H$2:$H$5000,$S$4,Transaction_Data!$E$2:$E$5000,$B90) -> 366 | D90: =SUMIFS(Transaction_Data!$F$2:$F$5000,Transaction_Data!$D$2:$D$5000,">="&$S$5,Transaction_Data!$D$2:$D$5000,"<"&$S$6,Transaction_Data!$H$2:$H$5000,$S$4,Transaction_Data!$E$2:$E$5000,$B90)/100000 -> 375.04321 | E90: =IFERROR(SUMIFS(Transaction_Data!$F$2:$F$5000,Transaction_Data!$D$2:$D$5000,">="&$S$5,Transaction_Data!$D$2:$D$5000,"<"&$S$6,Transaction_Data!$H$2:$H$5000,$S$4,Transaction_Data!$E$2:$E$5000,$B90)/C90,0) -> 102470.82 | F90: =IFERROR(COUNTIFS(Transaction_Data!$D$2:$D$5000,">="&$S$5,Transaction_Data!$D$2:$D$5000,"<"&$S$6,Transaction_Data!$H$2:$H$5000,$S$4,Transaction_Data!$E$2:$E$5000,$B90,Transaction_Data!$J$2:$J$5000,"Success")/C90,0) -> 0.8989071 | G90: =IFERROR(COUNTIFS(Transaction_Data!$D$2:$D$5000,">="&$S$5,Transaction_Data!$D$2:$D$5000,"<"&$S$6,Transaction_Data!$H$2:$H$5000,$S$4,Transaction_Data!$E$2:$E$5000,$B90,Transaction_Data!$J$2:$J$5000,"Failed")/C90,0) -> 0.06284153 | H90: =IFERROR(COUNTIFS(Transaction_Data!$D$2:$D$5000,">="&$S$5,Transaction_Data!$D$2:$D$5000,"<"&$S$6,Transaction_Data!$H$2:$H$5000,$S$4,Transaction_Data!$E$2:$E$5000,$B90,Transaction_Data!$J$2:$J$5000,"Pending")/C90,0) -> 0.038251366 | J90: 2 | K90: =INDEX($J$103:$J$132,MATCH(LARGE($M$103:$M$132,$J90),$M$103:$M$132,0)) -> Bandra | L90: =INDEX($K$103:$K$132,MATCH(LARGE($M$103:$M$132,$J90),$M$103:$M$132,0)) -> Mumbai | M90: =INDEX($L$103:$L$132,MATCH(LARGE($M$103:$M$132,$J90),$M$103:$M$132,0)) -> 113 | N90: =INDEX($M$103:$M$132,MATCH(LARGE($M$103:$M$132,$J90),$M$103:$M$132,0)) -> 114.70431
B91: IMPS | C91: =COUNTIFS(Transaction_Data!$D$2:$D$5000,">="&$S$5,Transaction_Data!$D$2:$D$5000,"<"&$S$6,Transaction_Data!$H$2:$H$5000,$S$4,Transaction_Data!$E$2:$E$5000,$B91) -> 369 | D91: =SUMIFS(Transaction_Data!$F$2:$F$5000,Transaction_Data!$D$2:$D$5000,">="&$S$5,Transaction_Data!$D$2:$D$5000,"<"&$S$6,Transaction_Data!$H$2:$H$5000,$S$4,Transaction_Data!$E$2:$E$5000,$B91)/100000 -> 379.71417 | E91: =IFERROR(SUMIFS(Transaction_Data!$F$2:$F$5000,Transaction_Data!$D$2:$D$5000,">="&$S$5,Transaction_Data!$D$2:$D$5000,"<"&$S$6,Transaction_Data!$H$2:$H$5000,$S$4,Transaction_Data!$E$2:$E$5000,$B91)/C91,0) -> 102903.57 | F91: =IFERROR(COUNTIFS(Transaction_Data!$D$2:$D$5000,">="&$S$5,Transaction_Data!$D$2:$D$5000,"<"&$S$6,Transaction_Data!$H$2:$H$5000,$S$4,Transaction_Data!$E$2:$E$5000,$B91,Transaction_Data!$J$2:$J$5000,"Success")/C91,0) -> 0.8699187 | G91: =IFERROR(COUNTIFS(Transaction_Data!$D$2:$D$5000,">="&$S$5,Transaction_Data!$D$2:$D$5000,"<"&$S$6,Transaction_Data!$H$2:$H$5000,$S$4,Transaction_Data!$E$2:$E$5000,$B91,Transaction_Data!$J$2:$J$5000,"Failed")/C91,0) -> 0.097560976 | H91: =IFERROR(COUNTIFS(Transaction_Data!$D$2:$D$5000,">="&$S$5,Transaction_Data!$D$2:$D$5000,"<"&$S$6,Transaction_Data!$H$2:$H$5000,$S$4,Transaction_Data!$E$2:$E$5000,$B91,Transaction_Data!$J$2:$J$5000,"Pending")/C91,0) -> 0.032520325 | J91: 3 | K91: =INDEX($J$103:$J$132,MATCH(LARGE($M$103:$M$132,$J91),$M$103:$M$132,0)) -> C-Scheme | L91: =INDEX($K$103:$K$132,MATCH(LARGE($M$103:$M$132,$J91),$M$103:$M$132,0)) -> Jaipur | M91: =INDEX($L$103:$L$132,MATCH(LARGE($M$103:$M$132,$J91),$M$103:$M$132,0)) -> 107 | N91: =INDEX($M$103:$M$132,MATCH(LARGE($M$103:$M$132,$J91),$M$103:$M$132,0)) -> 112.63045
...

Sheet Transaction_Data
A1: Transaction_ID | B1: Customer_ID | C1: Loan_ID | D1: Transaction_Date | E1: Transaction_Type | F1: Amount_INR | G1: Channel | H1: City | I1: Branch | J1: Transaction_Status | K1: Geography
A2: TXN000001 | B2: CUST0179 | D2: 46025 | E2: ATM | F2: 75403.9 | G2: ATM | H2: Kolkata | I2: Park Street | J2: Success | K2: International
A3: TXN000002 | B3: CUST0197 | D3: 45928 | E3: ATM | F3: 73013.28 | G3: Internet Banking | H3: Chennai | I3: T Nagar | J3: Success | K3: Domestic
A4: TXN000003 | B4: CUST0365 | D4: 46082 | E4: Card | F4: 142990.84 | G4: Branch | H4: Delhi | I4: Rohini | J4: Success | K4: Domestic
A5: TXN000004 | B5: CUST0639 | D5: 45780 | E5: Card | F5: 66523.95 | G5: POS | H5: Chennai | I5: OMR | J5: Success | K5: International
A6: TXN000005 | B6: CUST0571 | C6: LN00779 | D6: 46014 | E6: Cash Deposit | F6: 163092.9 | G6: Mobile App | H6: Delhi | I6: Rohini | J6: Pending | K6: Domestic
A7: TXN000006 | B7: CUST0175 | D7: 45663 | E7: Cash Withdrawal | F7: 106661.52 | G7: Internet Banking | H7: Lucknow | I7: Hazratganj | J7: Failed | K7: Domestic
A8: TXN000007 | B8: CUST0027 | D8: 46151 | E8: Card | F8: 51587.77 | G8: POS | H8: Bengaluru | I8: Electronic City | J8: Success | K8: Domestic
A9: TXN000008 | B9: CUST0290 | C9: LN00910 | D9: 45827 | E9: UPI | F9: 166445.1 | G9: Branch | H9: Jaipur | I9: C-Scheme | J9: Pending | K9: International
A10: TXN000009 | B10: CUST0515 | D10: 45799 | E10: Card | F10: 123112.14 | G10: Branch | H10: Hyderabad | I10: Banjara Hills | J10: Success | K10: Domestic
A11: TXN000010 | B11: CUST0635 | D11: 45997 | E11: Cash Deposit | F11: 196758.88 | G11: Mobile App | H11: Noida | I11: Sector 62 | J11: Success | K11: Domestic
A12: TXN000011 | B12: CUST0305 | D12: 45926 | E12: NEFT | F12: 91877.57 | G12: Internet Banking | H12: Pune | I12: Hinjewadi | J12: Success | K12: Domestic
A13: TXN000012 | B13: CUST0388 | D13: 46021 | E13: ATM | F13: 174801.24 | G13: ATM | H13: Pune | I13: Camp | J13: Success | K13: Domestic
A14: TXN000013 | B14: CUST0103 | D14: 45778 | E14: Cash Withdrawal | F14: 139244.31 | G14: Mobile App | H14: Jaipur | I14: Vaishali Nagar | J14: Failed | K14: International
A15: TXN000014 | B15: CUST0145 | C15: LN00447 | D15: 45869 | E15: Cash Withdrawal | F15: 196563.9 | G15: Mobile App | H15: Mumbai | I15: Bandra | J15: Success | K15: International
A16: TXN000015 | B16: CUST0633 | D16: 45942 | E16: Card | F16: 193254.93 | G16: Internet Banking | H16: Bengaluru | I16: Electronic City | J16: Pending | K16: International
A17: TXN000016 | B17: CUST0372 | D17: 46264 | E17: Cash Deposit | F17: 184496.82 | G17: Branch | H17: Mumbai | I17: Bandra | J17: Failed | K17: Domestic
A18: TXN000017 | B18: CUST0014 | D18: 46279 | E18: Cash Withdrawal | F18: 13505.01 | G18: ATM | H18: Bengaluru | I18: Electronic City | J18: Success | K18: International
A19: TXN000018 | B19: CUST0349 | D19: 45736 | E19: ATM | F19: 183606.92 | G19: Internet Banking | H19: Lucknow | I19: Hazratganj | J19: Success | K19: International
A20: TXN000019 | B20: CUST0286 | D20: 46144 | E20: Cash Deposit | F20: 40190.17 | G20: Mobile App | H20: Kolkata | I20: Salt Lake | J20: Success | K20: International
A21: TXN000020 | B21: CUST0524 | D21: 46165 | E21: Cash Deposit | F21: 64760.79 | G21: POS | H21: Pune | I21: Camp | J21: Success | K21: International
A22: TXN000021 | B22: CUST0441 | D22: 46189 | E22: UPI | F22: 26404.17 | G22: Mobile App | H22: Hyderabad | I22: Secunderabad | J22: Success | K22: International
A23: TXN000022 | B23: CUST0235 | D23: 45934 | E23: Cash Withdrawal | F23: 129952.7 | G23: POS | H23: Delhi | I23: Rohini | J23: Success | K23: International
A24: TXN000023 | B24: CUST0550 | C24: LN01058 | D24: 45683 | E24: Cash Withdrawal | F24: 78332.38 | G24: Internet Banking | H24: Pune | I24: Hinjewadi | J24: Failed | K24: Domestic
A25: TXN000024 | B25: CUST0726 | D25: 45945 | E25: Cash Withdrawal | F25: 155844.17 | G25: Internet Banking | H25: Bengaluru | I25: MG Road | J25: Success | K25: International
A26: TXN000025 | B26: CUST0250 | D26: 46023 | E26: NEFT | F26: 103346.11 | G26: Branch | H26: Mumbai | I26: Thane | J26: Success | K26: Domestic
A27: TXN000026 | B27: CUST0058 | D27: 45665 | E27: IMPS | F27: 82283.9 | G27: Branch | H27: Lucknow | I27: Aliganj | J27: Failed | K27: Domestic
A28: TXN000027 | B28: CUST0273 | D28: 46176 | E28: UPI | F28: 184769.56 | G28: Mobile App | H28: Chennai | I28: OMR | J28: Success | K28: Domestic
A29: TXN000028 | B29: CUST0674 | D29: 46020 | E29: IMPS | F29: 188720.5 | G29: Branch | H29: Pune | I29: Camp | J29: Success | K29: International
A30: TXN000029 | B30: CUST0175 | D30: 45790 | E30: Cash Deposit | F30: 41097.85 | G30: ATM | H30: Lucknow | I30: Hazratganj | J30: Success | K30: International
A31: TXN000030 | B31: CUST0748 | D31: 46292 | E31: Card | F31: 29544.52 | G31: ATM | H31: Mumbai | I31: Thane | J31: Success | K31: Domestic
A32: TXN000031 | B32: CUST0499 | D32: 46155 | E32: Cash Withdrawal | F32: 170248.28 | G32: Internet Banking | H32: Kolkata | I32: Salt Lake | J32: Success | K32: Domestic
A33: TXN000032 | B33: CUST0167 | D33: 45994 | E33: Cash Deposit | F33: 165626.07 | G33: Branch | H33: Mumbai | I33: Thane | J33: Success | K33: Domestic
A34: TXN000033 | B34: CUST0643 | C34: LN00874 | D34: 46050 | E34: IMPS | F34: 109244.2 | G34: Branch | H34: Noida | I34: Sector 18 | J34: Success | K34: Domestic
A35: TXN000034 | B35: CUST0509 | D35: 45802 | E35: Card | F35: 52933.7 | G35: ATM | H35: Jaipur | I35: Vaishali Nagar | J35: Success | K35: International
A36: TXN000035 | B36: CUST0536 | D36: 46143 | E36: IMPS | F36: 140973.52 | G36: Branch | H36: Pune | I36: Hinjewadi | J36: Success | K36: International
A37: TXN000036 | B37: CUST0115 | D37: 46108 | E37: ATM | F37: 151448.21 | G37: Branch | H37: Noida | I37: Sector 62 | J37: Success | K37: Domestic
A38: TXN000037 | B38: CUST0135 | D38: 46258 | E38: Cash Deposit | F38: 47491.44 | G38: Mobile App | H38: Mumbai | I38: Thane | J38: Success | K38: International
A39: TXN000038 | B39: CUST0562 | D39: 45905 | E39: ATM | F39: 5036.68 | G39: Mobile App | H39: Bengaluru | I39: Whitefield | J39: Success | K39: International
A40: TXN000039 | B40: CUST0515 | D40: 46244 | E40: UPI | F40: 72055.81 | G40: POS | H40: Hyderabad | I40: Banjara Hills | J40: Success | K40: International
...

Sheet Branch_Data
A1: Branch_ID | B1: City | C1: Branch | D1: Branch_Type
A2: BR001 | B2: Delhi | C2: Delhi Central | D2: Metro
A3: BR002 | B3: Delhi | C3: Rohini | D3: Semi-Urban
A4: BR003 | B4: Delhi | C4: Dwarka | D4: Semi-Urban
A5: BR004 | B5: Mumbai | C5: Andheri | D5: Metro
A6: BR005 | B6: Mumbai | C6: Bandra | D6: Semi-Urban
A7: BR006 | B7: Mumbai | C7: Thane | D7: Metro
A8: BR007 | B8: Bengaluru | C8: Whitefield | D8: Metro
A9: BR008 | B9: Bengaluru | C9: Electronic City | D9: Metro
A10: BR009 | B10: Bengaluru | C10: MG Road | D10: Urban
A11: BR010 | B11: Hyderabad | C11: Hitech City | D11: Urban
A12: BR011 | B12: Hyderabad | C12: Secunderabad | D12: Semi-Urban
... A31: BR030 | B31: Chennai | C31: Anna Nagar | D31: Metro
